{
  "configurations": {
    "CVE_data_version": "4.0",
    "nodes": [
      {
        "children": [],
        "cpe_match": [
          {
            "cpe23Uri": "cpe:2.3:a:python:python:*:*:*:*:*:*:*:*",
            "cpe_name": [],
            "versionEndExcluding": "3.7.10",
            "versionStartIncluding": "3.7.0",
            "vulnerable": true
          },
          {
            "cpe23Uri": "cpe:2.3:a:python:python:*:*:*:*:*:*:*:*",
            "cpe_name": [],
            "versionEndExcluding": "3.6.13",
            "vulnerable": true
          },
          {
            "cpe23Uri": "cpe:2.3:a:python:python:*:*:*:*:*:*:*:*",
            "cpe_name": [],
            "versionEndExcluding": "3.9.1",
            "versionStartIncluding": "3.9.0",
            "vulnerable": true
          },
          {
            "cpe23Uri": "cpe:2.3:a:python:python:*:*:*:*:*:*:*:*",
            "cpe_name": [],
            "versionEndExcluding": "3.8.7",
            "versionStartIncluding": "3.8.0",
            "vulnerable": true
          }
        ],
        "operator": "OR"
      },
      {
        "children": [],
        "cpe_match": [
          {
            "cpe23Uri": "cpe:2.3:o:debian:debian_linux:10.0:*:*:*:*:*:*:*",
            "cpe_name": [],
            "vulnerable": true
          }
        ],
        "operator": "OR"
      }
    ]
  },
  "cve": {
    "CVE_data_meta": {
      "ASSIGNER": "cve@mitre.org",
      "ID": "CVE-2022-48565"
    },
    "data_format": "MITRE",
    "data_type": "CVE",
    "data_version": "4.0",
    "description": {
      "description_data": [
        {
          "lang": "en",
          "value": "An XML External Entity (XXE) issue was discovered in Python through 3.9.1. The plistlib module no longer accepts entity declarations in XML plist files to avoid XML vulnerabilities."
        }
      ]
    },
    "problemtype": {
      "problemtype_data": [
        {
          "description": [
            {
              "lang": "en",
              "value": "CWE-611"
            }
          ]
        }
      ]
    },
    "references": {
      "reference_data": [
        {
          "name": "https://bugs.python.org/issue42051",
          "refsource": "MISC",
          "tags": [
            "Exploit",
            "Issue Tracking",
            "Patch",
            "Vendor Advisory"
          ],
          "url": "https://bugs.python.org/issue42051"
        },
        {
          "name": "[debian-lts-announce] 20230920 [SECURITY] [DLA 3575-1] python2.7 security update",
          "refsource": "MLIST",
          "tags": [
            "Third Party Advisory"
          ],
          "url": "https://lists.debian.org/debian-lts-announce/2023/09/msg00022.html"
        }
      ]
    }
  },
  "impact": {
    "baseMetricV3": {
      "cvssV3": {
        "attackComplexity": "LOW",
        "attackVector": "NETWORK",
        "availabilityImpact": "HIGH",
        "baseScore": 9.8,
        "baseSeverity": "CRITICAL",
        "confidentialityImpact": "HIGH",
        "integrityImpact": "HIGH",
        "privilegesRequired": "NONE",
        "scope": "UNCHANGED",
        "userInteraction": "NONE",
        "vectorString": "CVSS:3.1/AV:N/AC:L/PR:N/UI:N/S:U/C:H/I:H/A:H",
        "version": "3.1"
      },
      "exploitabilityScore": 3.9,
      "impactScore": 5.9
    }
  },
  "lastModifiedDate": "2023-09-28T16:06Z",
  "publishedDate": "2023-08-22T19:16Z"
}