{
  "configurations": {
    "CVE_data_version": "4.0",
    "nodes": []
  },
  "cve": {
    "CVE_data_meta": {
      "ASSIGNER": "cve@mitre.org",
      "ID": "CVE-2025-29606"
    },
    "data_format": "MITRE",
    "data_type": "CVE",
    "data_version": "4.0",
    "description": {
      "description_data": [
        {
          "lang": "en",
          "value": "py-libp2p before 0.2.3 allows a peer to cause a denial of service (resource consumption) via a large RSA key."
        }
      ]
    },
    "problemtype": {
      "problemtype_data": [
        {
          "description": [
            {
              "lang": "en",
              "value": "CWE-770"
            }
          ]
        }
      ]
    },
    "references": {
      "reference_data": [
        {
          "name": "https://github.com/libp2p/py-libp2p/compare/v0.2.2...v0.2.3",
          "refsource": "",
          "tags": [],
          "url": "https://github.com/libp2p/py-libp2p/compare/v0.2.2...v0.2.3"
        },
        {
          "name": "https://github.com/libp2p/py-libp2p/issues/526",
          "refsource": "",
          "tags": [],
          "url": "https://github.com/libp2p/py-libp2p/issues/526"
        },
        {
          "name": "https://github.com/libp2p/py-libp2p/pull/531/files",
          "refsource": "",
          "tags": [],
          "url": "https://github.com/libp2p/py-libp2p/pull/531/files"
        }
      ]
    }
  },
  "impact": {},
  "lastModifiedDate": "2025-07-14T05:15Z",
  "publishedDate": "2025-07-14T05:15Z"
}