{
  "configurations": {
    "CVE_data_version": "4.0",
    "nodes": []
  },
  "cve": {
    "CVE_data_meta": {
      "ASSIGNER": "secalert@redhat.com",
      "ID": "CVE-2024-1141"
    },
    "data_format": "MITRE",
    "data_type": "CVE",
    "data_version": "4.0",
    "description": {
      "description_data": [
        {
          "lang": "en",
          "value": "A vulnerability was found in python-glance-store. The issue occurs when the package logs the access_key for the glance-store when the DEBUG log level is enabled."
        }
      ]
    },
    "problemtype": {
      "problemtype_data": [
        {
          "description": []
        }
      ]
    },
    "references": {
      "reference_data": [
        {
          "name": "https://access.redhat.com/security/cve/CVE-2024-1141",
          "refsource": "",
          "tags": [],
          "url": "https://access.redhat.com/security/cve/CVE-2024-1141"
        },
        {
          "name": "RHBZ#2258836",
          "refsource": "",
          "tags": [],
          "url": "https://bugzilla.redhat.com/show_bug.cgi?id=2258836"
        }
      ]
    }
  },
  "impact": {},
  "lastModifiedDate": "2024-02-01T21:30Z",
  "publishedDate": "2024-02-01T15:15Z"
}